[2025-03-23T02:34:44.306+0000] {taskinstance.py:1159} INFO - Dependencies all met for dep_context=non-requeueable deps ti=<TaskInstance: entrenar_modelo.entrenar_modelo_rf manual__2025-03-23T02:33:27.187713+00:00 [queued]>
[2025-03-23T02:34:44.337+0000] {taskinstance.py:1159} INFO - Dependencies all met for dep_context=requeueable deps ti=<TaskInstance: entrenar_modelo.entrenar_modelo_rf manual__2025-03-23T02:33:27.187713+00:00 [queued]>
[2025-03-23T02:34:44.337+0000] {taskinstance.py:1361} INFO - Starting attempt 2 of 2
[2025-03-23T02:34:44.371+0000] {taskinstance.py:1382} INFO - Executing <Task(PythonOperator): entrenar_modelo_rf> on 2025-03-23 02:33:27.187713+00:00
[2025-03-23T02:34:44.413+0000] {standard_task_runner.py:57} INFO - Started process 87 to run task
[2025-03-23T02:34:44.427+0000] {standard_task_runner.py:84} INFO - Running: ['***', 'tasks', 'run', 'entrenar_modelo', 'entrenar_modelo_rf', 'manual__2025-03-23T02:33:27.187713+00:00', '--job-id', '20', '--raw', '--subdir', 'DAGS_FOLDER/entrenar_modelo.py', '--cfg-path', '/tmp/tmplbvzfdw3']
[2025-03-23T02:34:44.439+0000] {standard_task_runner.py:85} INFO - Job 20: Subtask entrenar_modelo_rf
[2025-03-23T02:34:44.539+0000] {task_command.py:415} INFO - Running <TaskInstance: entrenar_modelo.entrenar_modelo_rf manual__2025-03-23T02:33:27.187713+00:00 [running]> on host 19e876c2663b
[2025-03-23T02:34:44.773+0000] {taskinstance.py:1660} INFO - Exporting env vars: AIRFLOW_CTX_DAG_OWNER='***' AIRFLOW_CTX_DAG_ID='entrenar_modelo' AIRFLOW_CTX_TASK_ID='entrenar_modelo_rf' AIRFLOW_CTX_EXECUTION_DATE='2025-03-23T02:33:27.187713+00:00' AIRFLOW_CTX_TRY_NUMBER='2' AIRFLOW_CTX_DAG_RUN_ID='manual__2025-03-23T02:33:27.187713+00:00'
[2025-03-23T02:34:44.817+0000] {taskinstance.py:1943} ERROR - Task failed with exception
Traceback (most recent call last):
  File "/home/airflow/.local/lib/python3.9/site-packages/airflow/operators/python.py", line 192, in execute
    return_value = self.execute_callable()
  File "/home/airflow/.local/lib/python3.9/site-packages/airflow/operators/python.py", line 209, in execute_callable
    return self.python_callable(*self.op_args, **self.op_kwargs)
  File "/opt/airflow/dags/entrenar_modelo.py", line 45, in entrenar
    modelo.fit(X, y)
  File "/home/airflow/.local/lib/python3.9/site-packages/sklearn/base.py", line 1389, in wrapper
    return fit_method(estimator, *args, **kwargs)
  File "/home/airflow/.local/lib/python3.9/site-packages/sklearn/ensemble/_forest.py", line 360, in fit
    X, y = validate_data(
  File "/home/airflow/.local/lib/python3.9/site-packages/sklearn/utils/validation.py", line 2961, in validate_data
    X, y = check_X_y(X, y, **check_params)
  File "/home/airflow/.local/lib/python3.9/site-packages/sklearn/utils/validation.py", line 1370, in check_X_y
    X = check_array(
  File "/home/airflow/.local/lib/python3.9/site-packages/sklearn/utils/validation.py", line 1055, in check_array
    array = _asarray_with_order(array, order=order, dtype=dtype, xp=xp)
  File "/home/airflow/.local/lib/python3.9/site-packages/sklearn/utils/_array_api.py", line 839, in _asarray_with_order
    array = numpy.asarray(array, order=order, dtype=dtype)
  File "/home/airflow/.local/lib/python3.9/site-packages/pandas/core/generic.py", line 1998, in __array__
    arr = np.asarray(values, dtype=dtype)
ValueError: could not convert string to float: 'Rawah'
[2025-03-23T02:34:44.843+0000] {taskinstance.py:1400} INFO - Marking task as FAILED. dag_id=entrenar_modelo, task_id=entrenar_modelo_rf, execution_date=20250323T023327, start_date=20250323T023444, end_date=20250323T023444
[2025-03-23T02:34:44.858+0000] {standard_task_runner.py:104} ERROR - Failed to execute job 20 for task entrenar_modelo_rf (could not convert string to float: 'Rawah'; 87)
[2025-03-23T02:34:44.919+0000] {local_task_job_runner.py:228} INFO - Task exited with return code 1
[2025-03-23T02:34:44.962+0000] {taskinstance.py:2784} INFO - 0 downstream tasks scheduled from follow-on schedule check
