[2025-03-23T03:03:00.337+0000] {taskinstance.py:1159} INFO - Dependencies all met for dep_context=non-requeueable deps ti=<TaskInstance: entrenar_modelo.entrenar_modelo_rf manual__2025-03-23T03:01:16.809926+00:00 [queued]>
[2025-03-23T03:03:00.347+0000] {taskinstance.py:1159} INFO - Dependencies all met for dep_context=requeueable deps ti=<TaskInstance: entrenar_modelo.entrenar_modelo_rf manual__2025-03-23T03:01:16.809926+00:00 [queued]>
[2025-03-23T03:03:00.348+0000] {taskinstance.py:1361} INFO - Starting attempt 2 of 2
[2025-03-23T03:03:00.381+0000] {taskinstance.py:1382} INFO - Executing <Task(PythonOperator): entrenar_modelo_rf> on 2025-03-23 03:01:16.809926+00:00
[2025-03-23T03:03:00.414+0000] {standard_task_runner.py:57} INFO - Started process 139 to run task
[2025-03-23T03:03:00.432+0000] {standard_task_runner.py:84} INFO - Running: ['***', 'tasks', 'run', 'entrenar_modelo', 'entrenar_modelo_rf', 'manual__2025-03-23T03:01:16.809926+00:00', '--job-id', '30', '--raw', '--subdir', 'DAGS_FOLDER/entrenar_modelo.py', '--cfg-path', '/tmp/tmp8_dhnkbb']
[2025-03-23T03:03:00.449+0000] {standard_task_runner.py:85} INFO - Job 30: Subtask entrenar_modelo_rf
[2025-03-23T03:03:00.621+0000] {task_command.py:415} INFO - Running <TaskInstance: entrenar_modelo.entrenar_modelo_rf manual__2025-03-23T03:01:16.809926+00:00 [running]> on host 976ca539c8fa
[2025-03-23T03:03:00.781+0000] {taskinstance.py:1660} INFO - Exporting env vars: AIRFLOW_CTX_DAG_OWNER='***' AIRFLOW_CTX_DAG_ID='entrenar_modelo' AIRFLOW_CTX_TASK_ID='entrenar_modelo_rf' AIRFLOW_CTX_EXECUTION_DATE='2025-03-23T03:01:16.809926+00:00' AIRFLOW_CTX_TRY_NUMBER='2' AIRFLOW_CTX_DAG_RUN_ID='manual__2025-03-23T03:01:16.809926+00:00'
[2025-03-23T03:03:02.785+0000] {logging_mixin.py:151} WARNING - 2025/03/23 03:03:02 WARNING mlflow.utils.git_utils: Failed to import Git (the Git executable is probably not on your PATH), so Git SHA is not available. Error: Failed to initialize: Bad git executable.
The git executable must be specified in one of the following ways:
    - be included in your $PATH
    - be set via $GIT_PYTHON_GIT_EXECUTABLE
    - explicitly set via git.refresh(<full-path-to-git-executable>)

All git commands will error until this is rectified.

This initial message can be silenced or aggravated in the future by setting the
$GIT_PYTHON_REFRESH environment variable. Use one of the following values:
    - quiet|q|silence|s|silent|none|n|0: for no message or exception
    - warn|w|warning|log|l|1: for a warning message (logging level CRITICAL, displayed by default)
    - error|e|exception|raise|r|2: for a raised exception

Example:
    export GIT_PYTHON_REFRESH=quiet
[2025-03-23T03:03:20.650+0000] {logging_mixin.py:151} WARNING - 2025/03/23 03:03:20 WARNING mlflow.models.model: Model logged without a signature and input example. Please set `input_example` parameter when logging the model to auto infer the model signature.
[2025-03-23T03:03:21.122+0000] {credentials.py:1123} INFO - Found credentials in environment variables.
[2025-03-23T03:03:22.255+0000] {logging_mixin.py:151} INFO - üèÉ View run masked-ray-911 at: http://mlflow:5000/#/experiments/1/runs/de5fcd9156b841b7b2e33f0354dbd7bb
[2025-03-23T03:03:22.256+0000] {logging_mixin.py:151} INFO - üß™ View experiment at: http://mlflow:5000/#/experiments/1
[2025-03-23T03:03:22.280+0000] {taskinstance.py:1943} ERROR - Task failed with exception
Traceback (most recent call last):
  File "/home/airflow/.local/lib/python3.9/site-packages/airflow/operators/python.py", line 192, in execute
    return_value = self.execute_callable()
  File "/home/airflow/.local/lib/python3.9/site-packages/airflow/operators/python.py", line 209, in execute_callable
    return self.python_callable(*self.op_args, **self.op_kwargs)
  File "/opt/airflow/dags/entrenar_modelo.py", line 60, in entrenar
    joblib.dump(modelo, "/opt/airflow/modelos/modelo_rf.pkl")
  File "/home/airflow/.local/lib/python3.9/site-packages/joblib/numpy_pickle.py", line 552, in dump
    with open(filename, 'wb') as f:
FileNotFoundError: [Errno 2] No such file or directory: '/opt/airflow/modelos/modelo_rf.pkl'
[2025-03-23T03:03:22.315+0000] {taskinstance.py:1400} INFO - Marking task as FAILED. dag_id=entrenar_modelo, task_id=entrenar_modelo_rf, execution_date=20250323T030116, start_date=20250323T030300, end_date=20250323T030322
[2025-03-23T03:03:22.351+0000] {standard_task_runner.py:104} ERROR - Failed to execute job 30 for task entrenar_modelo_rf ([Errno 2] No such file or directory: '/opt/airflow/modelos/modelo_rf.pkl'; 139)
[2025-03-23T03:03:22.427+0000] {local_task_job_runner.py:228} INFO - Task exited with return code 1
[2025-03-23T03:03:22.453+0000] {taskinstance.py:2784} INFO - 0 downstream tasks scheduled from follow-on schedule check
