[2025-03-23T01:36:10.016+0000] {taskinstance.py:1159} INFO - Dependencies all met for dep_context=non-requeueable deps ti=<TaskInstance: recolectar_datos_api.extraer_datos manual__2025-03-23T01:36:07.502827+00:00 [queued]>
[2025-03-23T01:36:10.037+0000] {taskinstance.py:1159} INFO - Dependencies all met for dep_context=requeueable deps ti=<TaskInstance: recolectar_datos_api.extraer_datos manual__2025-03-23T01:36:07.502827+00:00 [queued]>
[2025-03-23T01:36:10.037+0000] {taskinstance.py:1361} INFO - Starting attempt 1 of 2
[2025-03-23T01:36:10.058+0000] {taskinstance.py:1382} INFO - Executing <Task(PythonOperator): extraer_datos> on 2025-03-23 01:36:07.502827+00:00
[2025-03-23T01:36:10.084+0000] {standard_task_runner.py:57} INFO - Started process 61 to run task
[2025-03-23T01:36:10.098+0000] {standard_task_runner.py:84} INFO - Running: ['***', 'tasks', 'run', 'recolectar_datos_api', 'extraer_datos', 'manual__2025-03-23T01:36:07.502827+00:00', '--job-id', '11', '--raw', '--subdir', 'DAGS_FOLDER/recolectar_datos.py', '--cfg-path', '/tmp/tmp549siwc1']
[2025-03-23T01:36:10.100+0000] {standard_task_runner.py:85} INFO - Job 11: Subtask extraer_datos
[2025-03-23T01:36:10.263+0000] {task_command.py:415} INFO - Running <TaskInstance: recolectar_datos_api.extraer_datos manual__2025-03-23T01:36:07.502827+00:00 [running]> on host 936a1b72c2fb
[2025-03-23T01:36:10.495+0000] {taskinstance.py:1660} INFO - Exporting env vars: AIRFLOW_CTX_DAG_OWNER='***' AIRFLOW_CTX_DAG_ID='recolectar_datos_api' AIRFLOW_CTX_TASK_ID='extraer_datos' AIRFLOW_CTX_EXECUTION_DATE='2025-03-23T01:36:07.502827+00:00' AIRFLOW_CTX_TRY_NUMBER='1' AIRFLOW_CTX_DAG_RUN_ID='manual__2025-03-23T01:36:07.502827+00:00'
[2025-03-23T01:36:10.731+0000] {taskinstance.py:1943} ERROR - Task failed with exception
Traceback (most recent call last):
  File "/home/airflow/.local/lib/python3.9/site-packages/airflow/operators/python.py", line 192, in execute
    return_value = self.execute_callable()
  File "/home/airflow/.local/lib/python3.9/site-packages/airflow/operators/python.py", line 209, in execute_callable
    return self.python_callable(*self.op_args, **self.op_kwargs)
  File "/opt/airflow/dags/recolectar_datos.py", line 23, in recolectar_lote
    with open(ruta, "w") as f:
PermissionError: [Errno 13] Permission denied: '/opt/airflow/datos_raw/lote_2.json'
[2025-03-23T01:36:10.763+0000] {taskinstance.py:1400} INFO - Marking task as UP_FOR_RETRY. dag_id=recolectar_datos_api, task_id=extraer_datos, execution_date=20250323T013607, start_date=20250323T013610, end_date=20250323T013610
[2025-03-23T01:36:10.795+0000] {standard_task_runner.py:104} ERROR - Failed to execute job 11 for task extraer_datos ([Errno 13] Permission denied: '/opt/airflow/datos_raw/lote_2.json'; 61)
[2025-03-23T01:36:10.883+0000] {local_task_job_runner.py:228} INFO - Task exited with return code 1
[2025-03-23T01:36:10.929+0000] {taskinstance.py:2784} INFO - 0 downstream tasks scheduled from follow-on schedule check
