[2025-03-23T01:37:12.402+0000] {taskinstance.py:1159} INFO - Dependencies all met for dep_context=non-requeueable deps ti=<TaskInstance: recolectar_datos_api.extraer_datos manual__2025-03-23T01:36:07.502827+00:00 [queued]>
[2025-03-23T01:37:12.429+0000] {taskinstance.py:1159} INFO - Dependencies all met for dep_context=requeueable deps ti=<TaskInstance: recolectar_datos_api.extraer_datos manual__2025-03-23T01:36:07.502827+00:00 [queued]>
[2025-03-23T01:37:12.430+0000] {taskinstance.py:1361} INFO - Starting attempt 2 of 2
[2025-03-23T01:37:12.457+0000] {taskinstance.py:1382} INFO - Executing <Task(PythonOperator): extraer_datos> on 2025-03-23 01:36:07.502827+00:00
[2025-03-23T01:37:12.478+0000] {standard_task_runner.py:57} INFO - Started process 63 to run task
[2025-03-23T01:37:12.494+0000] {standard_task_runner.py:84} INFO - Running: ['***', 'tasks', 'run', 'recolectar_datos_api', 'extraer_datos', 'manual__2025-03-23T01:36:07.502827+00:00', '--job-id', '12', '--raw', '--subdir', 'DAGS_FOLDER/recolectar_datos.py', '--cfg-path', '/tmp/tmpet7m27zc']
[2025-03-23T01:37:12.496+0000] {standard_task_runner.py:85} INFO - Job 12: Subtask extraer_datos
[2025-03-23T01:37:12.658+0000] {task_command.py:415} INFO - Running <TaskInstance: recolectar_datos_api.extraer_datos manual__2025-03-23T01:36:07.502827+00:00 [running]> on host 936a1b72c2fb
[2025-03-23T01:37:12.944+0000] {taskinstance.py:1660} INFO - Exporting env vars: AIRFLOW_CTX_DAG_OWNER='***' AIRFLOW_CTX_DAG_ID='recolectar_datos_api' AIRFLOW_CTX_TASK_ID='extraer_datos' AIRFLOW_CTX_EXECUTION_DATE='2025-03-23T01:36:07.502827+00:00' AIRFLOW_CTX_TRY_NUMBER='2' AIRFLOW_CTX_DAG_RUN_ID='manual__2025-03-23T01:36:07.502827+00:00'
[2025-03-23T01:37:13.089+0000] {taskinstance.py:1943} ERROR - Task failed with exception
Traceback (most recent call last):
  File "/home/airflow/.local/lib/python3.9/site-packages/airflow/operators/python.py", line 192, in execute
    return_value = self.execute_callable()
  File "/home/airflow/.local/lib/python3.9/site-packages/airflow/operators/python.py", line 209, in execute_callable
    return self.python_callable(*self.op_args, **self.op_kwargs)
  File "/opt/airflow/dags/recolectar_datos.py", line 23, in recolectar_lote
    with open(ruta, "w") as f:
PermissionError: [Errno 13] Permission denied: '/opt/airflow/datos_raw/lote_3.json'
[2025-03-23T01:37:13.114+0000] {taskinstance.py:1400} INFO - Marking task as FAILED. dag_id=recolectar_datos_api, task_id=extraer_datos, execution_date=20250323T013607, start_date=20250323T013712, end_date=20250323T013713
[2025-03-23T01:37:13.143+0000] {standard_task_runner.py:104} ERROR - Failed to execute job 12 for task extraer_datos ([Errno 13] Permission denied: '/opt/airflow/datos_raw/lote_3.json'; 63)
[2025-03-23T01:37:13.198+0000] {local_task_job_runner.py:228} INFO - Task exited with return code 1
[2025-03-23T01:37:13.257+0000] {taskinstance.py:2784} INFO - 0 downstream tasks scheduled from follow-on schedule check
