[2025-03-23T01:12:11.986+0000] {taskinstance.py:1159} INFO - Dependencies all met for dep_context=non-requeueable deps ti=<TaskInstance: recolectar_datos_api.extraer_datos manual__2025-03-23T01:11:08+00:00 [queued]>
[2025-03-23T01:12:11.998+0000] {taskinstance.py:1159} INFO - Dependencies all met for dep_context=requeueable deps ti=<TaskInstance: recolectar_datos_api.extraer_datos manual__2025-03-23T01:11:08+00:00 [queued]>
[2025-03-23T01:12:11.998+0000] {taskinstance.py:1361} INFO - Starting attempt 2 of 2
[2025-03-23T01:12:12.014+0000] {taskinstance.py:1382} INFO - Executing <Task(PythonOperator): extraer_datos> on 2025-03-23 01:11:08+00:00
[2025-03-23T01:12:12.049+0000] {standard_task_runner.py:57} INFO - Started process 55 to run task
[2025-03-23T01:12:12.065+0000] {standard_task_runner.py:84} INFO - Running: ['***', 'tasks', 'run', 'recolectar_datos_api', 'extraer_datos', 'manual__2025-03-23T01:11:08+00:00', '--job-id', '7', '--raw', '--subdir', 'DAGS_FOLDER/recolectar_datos.py', '--cfg-path', '/tmp/tmpg6bl0r_w']
[2025-03-23T01:12:12.071+0000] {standard_task_runner.py:85} INFO - Job 7: Subtask extraer_datos
[2025-03-23T01:12:12.245+0000] {task_command.py:415} INFO - Running <TaskInstance: recolectar_datos_api.extraer_datos manual__2025-03-23T01:11:08+00:00 [running]> on host 936a1b72c2fb
[2025-03-23T01:12:12.545+0000] {taskinstance.py:1660} INFO - Exporting env vars: AIRFLOW_CTX_DAG_OWNER='***' AIRFLOW_CTX_DAG_ID='recolectar_datos_api' AIRFLOW_CTX_TASK_ID='extraer_datos' AIRFLOW_CTX_EXECUTION_DATE='2025-03-23T01:11:08+00:00' AIRFLOW_CTX_TRY_NUMBER='2' AIRFLOW_CTX_DAG_RUN_ID='manual__2025-03-23T01:11:08+00:00'
[2025-03-23T01:12:12.594+0000] {taskinstance.py:1943} ERROR - Task failed with exception
Traceback (most recent call last):
  File "/home/airflow/.local/lib/python3.9/site-packages/urllib3/connection.py", line 174, in _new_conn
    conn = connection.create_connection(
  File "/home/airflow/.local/lib/python3.9/site-packages/urllib3/util/connection.py", line 72, in create_connection
    for res in socket.getaddrinfo(host, port, family, socket.SOCK_STREAM):
  File "/usr/local/lib/python3.9/socket.py", line 954, in getaddrinfo
    for res in _socket.getaddrinfo(host, port, family, type, proto, flags):
socket.gaierror: [Errno -2] Name or service not known

During handling of the above exception, another exception occurred:

Traceback (most recent call last):
  File "/home/airflow/.local/lib/python3.9/site-packages/urllib3/connectionpool.py", line 714, in urlopen
    httplib_response = self._make_request(
  File "/home/airflow/.local/lib/python3.9/site-packages/urllib3/connectionpool.py", line 415, in _make_request
    conn.request(method, url, **httplib_request_kw)
  File "/home/airflow/.local/lib/python3.9/site-packages/urllib3/connection.py", line 244, in request
    super(HTTPConnection, self).request(method, url, body=body, headers=headers)
  File "/usr/local/lib/python3.9/http/client.py", line 1285, in request
    self._send_request(method, url, body, headers, encode_chunked)
  File "/usr/local/lib/python3.9/http/client.py", line 1331, in _send_request
    self.endheaders(body, encode_chunked=encode_chunked)
  File "/usr/local/lib/python3.9/http/client.py", line 1280, in endheaders
    self._send_output(message_body, encode_chunked=encode_chunked)
  File "/usr/local/lib/python3.9/http/client.py", line 1040, in _send_output
    self.send(msg)
  File "/usr/local/lib/python3.9/http/client.py", line 980, in send
    self.connect()
  File "/home/airflow/.local/lib/python3.9/site-packages/urllib3/connection.py", line 205, in connect
    conn = self._new_conn()
  File "/home/airflow/.local/lib/python3.9/site-packages/urllib3/connection.py", line 186, in _new_conn
    raise NewConnectionError(
urllib3.exceptions.NewConnectionError: <urllib3.connection.HTTPConnection object at 0x7a6953842af0>: Failed to establish a new connection: [Errno -2] Name or service not known

During handling of the above exception, another exception occurred:

Traceback (most recent call last):
  File "/home/airflow/.local/lib/python3.9/site-packages/requests/adapters.py", line 486, in send
    resp = conn.urlopen(
  File "/home/airflow/.local/lib/python3.9/site-packages/urllib3/connectionpool.py", line 798, in urlopen
    retries = retries.increment(
  File "/home/airflow/.local/lib/python3.9/site-packages/urllib3/util/retry.py", line 592, in increment
    raise MaxRetryError(_pool, url, error or ResponseError(cause))
urllib3.exceptions.MaxRetryError: HTTPConnectionPool(host='host.docker.internal', port=80): Max retries exceeded with url: /data?group_number=10 (Caused by NewConnectionError('<urllib3.connection.HTTPConnection object at 0x7a6953842af0>: Failed to establish a new connection: [Errno -2] Name or service not known'))

During handling of the above exception, another exception occurred:

Traceback (most recent call last):
  File "/home/airflow/.local/lib/python3.9/site-packages/airflow/operators/python.py", line 192, in execute
    return_value = self.execute_callable()
  File "/home/airflow/.local/lib/python3.9/site-packages/airflow/operators/python.py", line 209, in execute_callable
    return self.python_callable(*self.op_args, **self.op_kwargs)
  File "/opt/airflow/dags/recolectar_datos.py", line 17, in recolectar_lote
    response = requests.get(url)
  File "/home/airflow/.local/lib/python3.9/site-packages/requests/api.py", line 73, in get
    return request("get", url, params=params, **kwargs)
  File "/home/airflow/.local/lib/python3.9/site-packages/requests/api.py", line 59, in request
    return session.request(method=method, url=url, **kwargs)
  File "/home/airflow/.local/lib/python3.9/site-packages/requests/sessions.py", line 589, in request
    resp = self.send(prep, **send_kwargs)
  File "/home/airflow/.local/lib/python3.9/site-packages/requests/sessions.py", line 703, in send
    r = adapter.send(request, **kwargs)
  File "/home/airflow/.local/lib/python3.9/site-packages/requests/adapters.py", line 519, in send
    raise ConnectionError(e, request=request)
requests.exceptions.ConnectionError: HTTPConnectionPool(host='host.docker.internal', port=80): Max retries exceeded with url: /data?group_number=10 (Caused by NewConnectionError('<urllib3.connection.HTTPConnection object at 0x7a6953842af0>: Failed to establish a new connection: [Errno -2] Name or service not known'))
[2025-03-23T01:12:12.623+0000] {taskinstance.py:1400} INFO - Marking task as FAILED. dag_id=recolectar_datos_api, task_id=extraer_datos, execution_date=20250323T011108, start_date=20250323T011211, end_date=20250323T011212
[2025-03-23T01:12:12.654+0000] {standard_task_runner.py:104} ERROR - Failed to execute job 7 for task extraer_datos (HTTPConnectionPool(host='host.docker.internal', port=80): Max retries exceeded with url: /data?group_number=10 (Caused by NewConnectionError('<urllib3.connection.HTTPConnection object at 0x7a6953842af0>: Failed to establish a new connection: [Errno -2] Name or service not known')); 55)
[2025-03-23T01:12:12.733+0000] {local_task_job_runner.py:228} INFO - Task exited with return code 1
[2025-03-23T01:12:12.774+0000] {taskinstance.py:2784} INFO - 0 downstream tasks scheduled from follow-on schedule check
