[2025-03-23T03:22:53.836+0000] {taskinstance.py:1159} INFO - Dependencies all met for dep_context=non-requeueable deps ti=<TaskInstance: entrenar_modelo.entrenar_modelo_rf manual__2025-03-23T03:21:15.505701+00:00 [queued]>
[2025-03-23T03:22:53.848+0000] {taskinstance.py:1159} INFO - Dependencies all met for dep_context=requeueable deps ti=<TaskInstance: entrenar_modelo.entrenar_modelo_rf manual__2025-03-23T03:21:15.505701+00:00 [queued]>
[2025-03-23T03:22:53.849+0000] {taskinstance.py:1361} INFO - Starting attempt 2 of 2
[2025-03-23T03:22:53.874+0000] {taskinstance.py:1382} INFO - Executing <Task(PythonOperator): entrenar_modelo_rf> on 2025-03-23 03:21:15.505701+00:00
[2025-03-23T03:22:53.927+0000] {standard_task_runner.py:57} INFO - Started process 100 to run task
[2025-03-23T03:22:53.950+0000] {standard_task_runner.py:84} INFO - Running: ['***', 'tasks', 'run', 'entrenar_modelo', 'entrenar_modelo_rf', 'manual__2025-03-23T03:21:15.505701+00:00', '--job-id', '34', '--raw', '--subdir', 'DAGS_FOLDER/entrenar_modelo.py', '--cfg-path', '/tmp/tmpy2wgc076']
[2025-03-23T03:22:53.960+0000] {standard_task_runner.py:85} INFO - Job 34: Subtask entrenar_modelo_rf
[2025-03-23T03:22:54.120+0000] {task_command.py:415} INFO - Running <TaskInstance: entrenar_modelo.entrenar_modelo_rf manual__2025-03-23T03:21:15.505701+00:00 [running]> on host 5cddd739e827
[2025-03-23T03:22:54.298+0000] {taskinstance.py:1660} INFO - Exporting env vars: AIRFLOW_CTX_DAG_OWNER='***' AIRFLOW_CTX_DAG_ID='entrenar_modelo' AIRFLOW_CTX_TASK_ID='entrenar_modelo_rf' AIRFLOW_CTX_EXECUTION_DATE='2025-03-23T03:21:15.505701+00:00' AIRFLOW_CTX_TRY_NUMBER='2' AIRFLOW_CTX_DAG_RUN_ID='manual__2025-03-23T03:21:15.505701+00:00'
[2025-03-23T03:22:55.932+0000] {logging_mixin.py:151} WARNING - 2025/03/23 03:22:55 WARNING mlflow.utils.git_utils: Failed to import Git (the Git executable is probably not on your PATH), so Git SHA is not available. Error: Failed to initialize: Bad git executable.
The git executable must be specified in one of the following ways:
    - be included in your $PATH
    - be set via $GIT_PYTHON_GIT_EXECUTABLE
    - explicitly set via git.refresh(<full-path-to-git-executable>)

All git commands will error until this is rectified.

This initial message can be silenced or aggravated in the future by setting the
$GIT_PYTHON_REFRESH environment variable. Use one of the following values:
    - quiet|q|silence|s|silent|none|n|0: for no message or exception
    - warn|w|warning|log|l|1: for a warning message (logging level CRITICAL, displayed by default)
    - error|e|exception|raise|r|2: for a raised exception

Example:
    export GIT_PYTHON_REFRESH=quiet
[2025-03-23T03:23:08.213+0000] {logging_mixin.py:151} WARNING - 2025/03/23 03:23:08 WARNING mlflow.models.model: Model logged without a signature and input example. Please set `input_example` parameter when logging the model to auto infer the model signature.
[2025-03-23T03:23:08.632+0000] {credentials.py:1123} INFO - Found credentials in environment variables.
[2025-03-23T03:23:09.503+0000] {logging_mixin.py:151} INFO - üèÉ View run hilarious-doe-748 at: http://mlflow:5000/#/experiments/1/runs/bc508e193e384255a3ed699f9a4fa0ae
[2025-03-23T03:23:09.504+0000] {logging_mixin.py:151} INFO - üß™ View experiment at: http://mlflow:5000/#/experiments/1
[2025-03-23T03:23:09.525+0000] {taskinstance.py:1943} ERROR - Task failed with exception
Traceback (most recent call last):
  File "/home/airflow/.local/lib/python3.9/site-packages/airflow/operators/python.py", line 192, in execute
    return_value = self.execute_callable()
  File "/home/airflow/.local/lib/python3.9/site-packages/airflow/operators/python.py", line 209, in execute_callable
    return self.python_callable(*self.op_args, **self.op_kwargs)
  File "/opt/airflow/dags/entrenar_modelo.py", line 60, in entrenar
    joblib.dump(modelo, "/opt/airflow/modelos/modelo_rf.pkl")
  File "/home/airflow/.local/lib/python3.9/site-packages/joblib/numpy_pickle.py", line 552, in dump
    with open(filename, 'wb') as f:
PermissionError: [Errno 13] Permission denied: '/opt/airflow/modelos/modelo_rf.pkl'
[2025-03-23T03:23:09.553+0000] {taskinstance.py:1400} INFO - Marking task as FAILED. dag_id=entrenar_modelo, task_id=entrenar_modelo_rf, execution_date=20250323T032115, start_date=20250323T032253, end_date=20250323T032309
[2025-03-23T03:23:09.574+0000] {standard_task_runner.py:104} ERROR - Failed to execute job 34 for task entrenar_modelo_rf ([Errno 13] Permission denied: '/opt/airflow/modelos/modelo_rf.pkl'; 100)
[2025-03-23T03:23:09.663+0000] {local_task_job_runner.py:228} INFO - Task exited with return code 1
[2025-03-23T03:23:09.694+0000] {taskinstance.py:2784} INFO - 0 downstream tasks scheduled from follow-on schedule check
