[2025-03-23T02:55:50.796+0000] {taskinstance.py:1159} INFO - Dependencies all met for dep_context=non-requeueable deps ti=<TaskInstance: entrenar_modelo.entrenar_modelo_rf manual__2025-03-23T02:55:37.427185+00:00 [queued]>
[2025-03-23T02:55:50.816+0000] {taskinstance.py:1159} INFO - Dependencies all met for dep_context=requeueable deps ti=<TaskInstance: entrenar_modelo.entrenar_modelo_rf manual__2025-03-23T02:55:37.427185+00:00 [queued]>
[2025-03-23T02:55:50.816+0000] {taskinstance.py:1361} INFO - Starting attempt 1 of 2
[2025-03-23T02:55:50.844+0000] {taskinstance.py:1382} INFO - Executing <Task(PythonOperator): entrenar_modelo_rf> on 2025-03-23 02:55:37.427185+00:00
[2025-03-23T02:55:50.876+0000] {standard_task_runner.py:57} INFO - Started process 71 to run task
[2025-03-23T02:55:50.894+0000] {standard_task_runner.py:84} INFO - Running: ['***', 'tasks', 'run', 'entrenar_modelo', 'entrenar_modelo_rf', 'manual__2025-03-23T02:55:37.427185+00:00', '--job-id', '26', '--raw', '--subdir', 'DAGS_FOLDER/entrenar_modelo.py', '--cfg-path', '/tmp/tmpb740p9i3']
[2025-03-23T02:55:50.907+0000] {standard_task_runner.py:85} INFO - Job 26: Subtask entrenar_modelo_rf
[2025-03-23T02:55:51.034+0000] {task_command.py:415} INFO - Running <TaskInstance: entrenar_modelo.entrenar_modelo_rf manual__2025-03-23T02:55:37.427185+00:00 [running]> on host 976ca539c8fa
[2025-03-23T02:55:51.246+0000] {taskinstance.py:1660} INFO - Exporting env vars: AIRFLOW_CTX_DAG_OWNER='***' AIRFLOW_CTX_DAG_ID='entrenar_modelo' AIRFLOW_CTX_TASK_ID='entrenar_modelo_rf' AIRFLOW_CTX_EXECUTION_DATE='2025-03-23T02:55:37.427185+00:00' AIRFLOW_CTX_TRY_NUMBER='1' AIRFLOW_CTX_DAG_RUN_ID='manual__2025-03-23T02:55:37.427185+00:00'
[2025-03-23T02:55:54.351+0000] {logging_mixin.py:151} WARNING - 2025/03/23 02:55:54 WARNING mlflow.utils.git_utils: Failed to import Git (the Git executable is probably not on your PATH), so Git SHA is not available. Error: Failed to initialize: Bad git executable.
The git executable must be specified in one of the following ways:
    - be included in your $PATH
    - be set via $GIT_PYTHON_GIT_EXECUTABLE
    - explicitly set via git.refresh(<full-path-to-git-executable>)

All git commands will error until this is rectified.

This initial message can be silenced or aggravated in the future by setting the
$GIT_PYTHON_REFRESH environment variable. Use one of the following values:
    - quiet|q|silence|s|silent|none|n|0: for no message or exception
    - warn|w|warning|log|l|1: for a warning message (logging level CRITICAL, displayed by default)
    - error|e|exception|raise|r|2: for a raised exception

Example:
    export GIT_PYTHON_REFRESH=quiet
[2025-03-23T02:56:10.186+0000] {logging_mixin.py:151} WARNING - 2025/03/23 02:56:10 WARNING mlflow.models.model: Model logged without a signature and input example. Please set `input_example` parameter when logging the model to auto infer the model signature.
[2025-03-23T02:56:11.398+0000] {credentials.py:1123} INFO - Found credentials in environment variables.
[2025-03-23T02:56:13.927+0000] {logging_mixin.py:151} INFO - üèÉ View run caring-ray-755 at: http://mlflow:5000/#/experiments/1/runs/8c0c61f8cc1c4a6e9facb40660e004c9
[2025-03-23T02:56:13.928+0000] {logging_mixin.py:151} INFO - üß™ View experiment at: http://mlflow:5000/#/experiments/1
[2025-03-23T02:56:14.005+0000] {taskinstance.py:1943} ERROR - Task failed with exception
Traceback (most recent call last):
  File "/home/airflow/.local/lib/python3.9/site-packages/boto3/s3/transfer.py", line 292, in upload_file
    future.result()
  File "/home/airflow/.local/lib/python3.9/site-packages/s3transfer/futures.py", line 103, in result
    return self._coordinator.result()
  File "/home/airflow/.local/lib/python3.9/site-packages/s3transfer/futures.py", line 266, in result
    raise self._exception
  File "/home/airflow/.local/lib/python3.9/site-packages/s3transfer/tasks.py", line 139, in __call__
    return self._execute_main(kwargs)
  File "/home/airflow/.local/lib/python3.9/site-packages/s3transfer/tasks.py", line 162, in _execute_main
    return_value = self._main(**kwargs)
  File "/home/airflow/.local/lib/python3.9/site-packages/s3transfer/upload.py", line 758, in _main
    client.put_object(Bucket=bucket, Key=key, Body=body, **extra_args)
  File "/home/airflow/.local/lib/python3.9/site-packages/botocore/client.py", line 535, in _api_call
    return self._make_api_call(operation_name, kwargs)
  File "/home/airflow/.local/lib/python3.9/site-packages/botocore/client.py", line 980, in _make_api_call
    raise error_class(parsed_response, operation_name)
botocore.errorfactory.NoSuchBucket: An error occurred (NoSuchBucket) when calling the PutObject operation: The specified bucket does not exist

During handling of the above exception, another exception occurred:

Traceback (most recent call last):
  File "/home/airflow/.local/lib/python3.9/site-packages/airflow/operators/python.py", line 192, in execute
    return_value = self.execute_callable()
  File "/home/airflow/.local/lib/python3.9/site-packages/airflow/operators/python.py", line 209, in execute_callable
    return self.python_callable(*self.op_args, **self.op_kwargs)
  File "/opt/airflow/dags/entrenar_modelo.py", line 57, in entrenar
    mlflow.sklearn.log_model(modelo, "modelo_entrenado")
  File "/home/airflow/.local/lib/python3.9/site-packages/mlflow/sklearn/__init__.py", line 413, in log_model
    return Model.log(
  File "/home/airflow/.local/lib/python3.9/site-packages/mlflow/models/model.py", line 932, in log
    mlflow.tracking.fluent.log_artifacts(local_path, mlflow_model.artifact_path, run_id)
  File "/home/airflow/.local/lib/python3.9/site-packages/mlflow/tracking/fluent.py", line 1219, in log_artifacts
    MlflowClient().log_artifacts(run_id, local_dir, artifact_path)
  File "/home/airflow/.local/lib/python3.9/site-packages/mlflow/tracking/client.py", line 2426, in log_artifacts
    self._tracking_client.log_artifacts(run_id, local_dir, artifact_path)
  File "/home/airflow/.local/lib/python3.9/site-packages/mlflow/tracking/_tracking_service/client.py", line 959, in log_artifacts
    self._get_artifact_repo(run_id).log_artifacts(local_dir, artifact_path)
  File "/home/airflow/.local/lib/python3.9/site-packages/mlflow/store/artifact/s3_artifact_repo.py", line 194, in log_artifacts
    self._upload_file(
  File "/home/airflow/.local/lib/python3.9/site-packages/mlflow/store/artifact/s3_artifact_repo.py", line 169, in _upload_file
    s3_client.upload_file(Filename=local_file, Bucket=bucket, Key=key, ExtraArgs=extra_args)
  File "/home/airflow/.local/lib/python3.9/site-packages/boto3/s3/inject.py", line 143, in upload_file
    return transfer.upload_file(
  File "/home/airflow/.local/lib/python3.9/site-packages/boto3/s3/transfer.py", line 298, in upload_file
    raise S3UploadFailedError(
boto3.exceptions.S3UploadFailedError: Failed to upload /tmp/tmp3p2j58az/model/requirements.txt to mlflow/1/8c0c61f8cc1c4a6e9facb40660e004c9/artifacts/modelo_entrenado/requirements.txt: An error occurred (NoSuchBucket) when calling the PutObject operation: The specified bucket does not exist
[2025-03-23T02:56:14.127+0000] {taskinstance.py:1400} INFO - Marking task as UP_FOR_RETRY. dag_id=entrenar_modelo, task_id=entrenar_modelo_rf, execution_date=20250323T025537, start_date=20250323T025550, end_date=20250323T025614
[2025-03-23T02:56:14.174+0000] {standard_task_runner.py:104} ERROR - Failed to execute job 26 for task entrenar_modelo_rf (Failed to upload /tmp/tmp3p2j58az/model/requirements.txt to mlflow/1/8c0c61f8cc1c4a6e9facb40660e004c9/artifacts/modelo_entrenado/requirements.txt: An error occurred (NoSuchBucket) when calling the PutObject operation: The specified bucket does not exist; 71)
[2025-03-23T02:56:14.298+0000] {local_task_job_runner.py:228} INFO - Task exited with return code 1
[2025-03-23T02:56:14.332+0000] {taskinstance.py:2784} INFO - 0 downstream tasks scheduled from follow-on schedule check
